<?xml version="1.0" ?>
<!-- =================================================================================== -->
<!-- |    This document was autogenerated by xacro from robot_car.xacro                | -->
<!-- |    EDITING THIS FILE BY HAND IS NOT RECOMMENDED                                 | -->
<!-- =================================================================================== -->
<robot name="robot_car">
  <xacro:include filename="$(find epi1)/src/models/robot_car/robot_car.gazebo" /> 
  <gazebo reference="base_link">
    <material>Gazebo/Orange</material>
  </gazebo>
  <link name="base_link">
    <pose>0 0 0 0 0 0</pose>
  </link>
  <joint name="base_link_to_chassis" type="fixed">
    <child link="chassis_link"/>
    <parent link="base_link"/>
  </joint>
  <!-- Define the chassis of the differential drive robot, which is our base -->
  <link name="chassis_link">
    <pose>0 0 0 0 0 0</pose>
    <!-- Define inertial system for the chassis -->
    <inertial>
      <mass value="10.0"/>
      <inertia ixx="0.09375" ixy="0" ixz="0" iyy="0.22708333333333333" iyz="0" izz="0.22708333333333333"/>
    </inertial>
    <!-- Define collision sorrounding box -->
    <collision name="collision">
      <origin rpy=" 0 0 0" xyz="0 0 0"/>
      <geometry>
        <box size="0.5 0.3 0.15"/>
      </geometry>
    </collision>
    <!-- Define visualization structure -->
    <visual name="base_link_visual">
      <origin rpy=" 0 0 0" xyz="0 0 0"/>
      <geometry>
        <box size="0.5 0.3 0.15"/>
      </geometry>
    </visual>
    <!-- Add the caster wheel! Here we simply assume complete slippage, thus we do not require that it rotates! -->
    <collision name="caster_collision">
      <origin rpy=" 0 0 0" xyz="0.19625 0 -0.075"/>
      <geometry>
        <sphere radius="0.05375"/>
      </geometry>
      <surface>
        <friction>
          <ode>
            <mu>0</mu>
            <mu2>0</mu2>
            <slip1>1.0</slip1>
            <slip2>1.0</slip2>
          </ode>
        </friction>
      </surface>
    </collision>
    <visual name="caster_visual">
      <origin rpy=" 0 0 0" xyz="0.19625 0 -0.075"/>
      <geometry>
        <sphere radius="0.05375"/>
      </geometry>
    </visual>
  </link>
  <!-- Add the wheels for the robot -->
  <link name="left_wheel">
    <collision name="collision">
      <origin rpy="0 1.5707 1.5707" xyz="0 0 0"/>
      <geometry>
        <cylinder length="0.03" radius="0.1075"/>
      </geometry>
      <surface>
        <friction>
          <ode>
            <mu>1.0</mu>
            <mu2>1.0</mu2>
            <slip1>0.0</slip1>
            <slip2>0.0</slip2>
          </ode>
        </friction>
      </surface>
    </collision>
    <visual name="left_wheel_visual">
      <origin rpy="0 1.5707 1.5707" xyz="0 0 0"/>
      <geometry>
        <cylinder length="0.03" radius="0.1075"/>
      </geometry>
    </visual>
    <inertial>
      <origin rpy="0 1.5707 1.5707" xyz="0 0 0"/>
      <mass value="3.0"/>
      <inertia ixx="0.008892187499999999" ixy="0" ixz="0" iyy="0.008892187499999999" iyz="0" izz="0.017334375"/>
    </inertial>
  </link>
  <link name="right_wheel">
    <collision name="collision">
      <origin rpy="0 1.5707 1.5707" xyz="0 0 0"/>
      <geometry>
        <cylinder length="0.03" radius="0.1075"/>
      </geometry>
      <surface>
        <friction>
          <ode>
            <mu>1.0</mu>
            <mu2>1.0</mu2>
            <slip1>0.0</slip1>
            <slip2>0.0</slip2>
          </ode>
        </friction>
      </surface>
    </collision>
    <visual name="right_wheel_visual">
      <origin rpy="0 1.5707 1.5707" xyz="0 0 0"/>
      <geometry>
        <cylinder length="0.03" radius="0.1075"/>
      </geometry>
    </visual>
    <inertial>
      <origin rpy="0 1.5707 1.5707" xyz="0 0 0"/>
      <mass value="3.0"/>
      <inertia ixx="0.008892187499999999" ixy="0" ixz="0" iyy="0.008892187499999999" iyz="0" izz="0.017334375"/>
    </inertial>
  </link>
  <!-- Set joints for the wheels which can be controlled over ROS -->
  <joint name="left_wheel_hinge" type="continuous">
    <origin rpy="0 0 0" xyz="-0.125 0.16499999999999998 -0.021249999999999998"/>
    <child link="left_wheel"/>
    <parent link="base_link"/>
    <axis rpy="0 0 0" xyz="0 1 0"/>
    <limit effort="100" velocity="100"/>
    <joint_properties damping="0.0" friction="0.0"/>
  </joint>
  <joint name="right_wheel_hinge" type="continuous">
    <origin rpy="0 0 0" xyz="-0.125 -0.16499999999999998 -0.021249999999999998"/>
    <child link="right_wheel"/>
    <parent link="base_link"/>
    <axis rpy="0 0 0" xyz="0 1 0"/>
    <limit effort="100" velocity="100"/>
    <joint_properties damping="0.0" friction="0.0"/>
  </joint>
</robot>

